Workbook

Sheet README
A1: YouTube Audience & Content Analysis Project
A2: Excel-based analytics project | BBA | Data analysis, KPI design, dashboarding and business recommendations
A4: 1. Problem statement
A5: A YouTube creator wants to know what content to make, when to publish it, and who is watching, so that views, engagement and subscribers grow faster.
A6: This project analyses video-level performance and audience demographics to answer those questions with evidence.
A8: 2. Objectives
A9: - Measure channel performance with KPIs: views, watch time, CTR, engagement rate, subscriber conversion.
A10: - Compare content categories, formats (Long-form vs Shorts) and video-length buckets.
A11: - Find the best publishing days and understand monthly growth, with a simple 3-month trend forecast.
A12: - Profile the audience by age, gender, country, device and traffic source.
A13: - Test relationships between variables using correlation and regression.
A14: - Convert findings into clear, data-backed content and publishing recommendations.
... A50: - Add competitor benchmarking and cohort analysis of subscribers gained per upload.

Sheet Dashboard
A1: YouTube Audience & Content Analysis Dashboard
A2: Sample dataset: 144 videos, Sep 2025 - Aug 2026 (illustrative). All tiles and charts are formula-driven.
A4: Total Videos | C4: Total Views | E4: Watch Hours | G4: Subscribers Gained | I4: Avg Views / Video | K4: Overall CTR | M4: Engagement Rate | O4: Top Category (avg views)
A5: =COUNTA(Videos_Data!$A$2:$A$145) -> 144 | C5: =SUM(Videos_Data!$H$2:$H$145) -> 5798478 | E5: =SUM(Videos_Data!$L$2:$L$145) -> 334375.8 | G5: =SUM(Videos_Data!$M$2:$M$145) -> 22063 | I5: =SUM(Videos_Data!$H$2:$H$145)/COUNTA(Videos_Data!$A$2:$A$145) -> 40267.208 | K5: =SUM(Videos_Data!$H$2:$H$145)/SUM(Videos_Data!$G$2:$G$145) -> 0.063523135 | M5: =(SUM(Videos_Data!$I$2:$I$145)+SUM(Videos_Data!$J$2:$J$145)+SUM(Videos_Data!$K$2:$K$145))/SUM(Videos_Data!$H$2:$H$145) -> 0.046621717 | O5: =Insights!C5 -> Career Guidance

Sheet Insights
A1: Key Insights & Recommendations
A2: Every finding below is a live formula, so it updates automatically if the data changes.
A4: # | B4: Question | C4: Finding | D4: Key Metric | E4: Value
A5: 1 | B5: Which content category earns the most views per video? | C5: =INDEX(Content_Analysis!$A$5:$A$10,MATCH(MAX(Content_Analysis!$D$5:$D$10),Content_Analysis!$D$5:$D$10,0)) -> Career Guidance | D5: Avg views per video | E5: =MAX(Content_Analysis!$D$5:$D$10) -> 54498.385
A6: 2 | B6: Which category has the highest engagement rate? | C6: =INDEX(Content_Analysis!$A$5:$A$10,MATCH(MAX(Content_Analysis!$H$5:$H$10),Content_Analysis!$H$5:$H$10,0)) -> Campus Vlogs | D6: Engagement rate | E6: =MAX(Content_Analysis!$H$5:$H$10) -> 0.062623449
A7: 3 | B7: Which category converts viewers into subscribers best? | C7: =INDEX(Content_Analysis!$A$5:$A$10,MATCH(MAX(Content_Analysis!$J$5:$J$10),Content_Analysis!$J$5:$J$10,0)) -> Career Guidance | D7: Sub conversion | E7: =MAX(Content_Analysis!$J$5:$J$10) -> 0.0042555954
A8: 4 | B8: Which publishing day gives the highest avg views? | C8: =INDEX(Timing_Trends!$A$5:$A$11,MATCH(MAX(Timing_Trends!$D$5:$D$11),Timing_Trends!$D$5:$D$11,0)) -> Sat | D8: Avg views per video | E8: =MAX(Timing_Trends!$D$5:$D$11) -> 52320.783
A9: 5 | B9: Do weekend or weekday uploads perform better? | C9: =IF(Timing_Trends!D18>=Timing_Trends!D17,"Weekend","Weekday") -> Weekend | D9: Lift over the other group | E9: =MAX(Timing_Trends!D17,Timing_Trends!D18)/MIN(Timing_Trends!D17,Timing_Trends!D18)-1 -> 0.21459849
A10: 6 | B10: Which long-form video length gets the most avg views? | C10: =INDEX(Content_Analysis!$A$24:$A$27,MATCH(MAX(Content_Analysis!$D$24:$D$27),Content_Analysis!$D$24:$D$27,0)) -> 5-10 min | D10: Avg views per video | E10: =MAX(Content_Analysis!$D$24:$D$27) -> 37628.87
A11: 7 | B11: Which format gets more avg views: Long-form or Short? | C11: =INDEX(Content_Analysis!$A$16:$A$17,MATCH(MAX(Content_Analysis!$D$16:$D$17),Content_Analysis!$D$16:$D$17,0)) -> Short | D11: Avg views per video | E11: =MAX(Content_Analysis!$D$16:$D$17) -> 62866.472
A12: 8 | B12: Which format drives most watch time? | C12: =IF(Content_Analysis!E16>=Content_Analysis!E17,"Long-form","Short") -> Long-form | D12: Share of total watch hours | E12: =MAX(Content_Analysis!E16,Content_Analysis!E17)/Content_Analysis!E18 -> 0.93784329
A13: 9 | B13: What is the largest traffic source? | C13: =INDEX(Audience_Data!$A$43:$A$49,MATCH(MAX(Audience_Data!$B$43:$B$49),Audience_Data!$B$43:$B$49,0)) -> Suggested videos | D13: Share of views | E13: =MAX(Audience_Data!$B$43:$B$49) -> 0.27
A14: 10 | B14: Which age group watches the most? | C14: =INDEX(Audience_Data!$A$7:$A$12,MATCH(MAX(Audience_Data!$E$7:$E$12),Audience_Data!$E$7:$E$12,0)) -> 18-24 | D14: Share of views | E14: =MAX(Audience_Data!$E$7:$E$12) -> 0.43
A15: 11 | B15: Which country brings the most views? | C15: =INDEX(Audience_Data!$A$24:$A$29,MATCH(MAX(Audience_Data!$B$24:$B$29),Audience_Data!$B$24:$B$29,0)) -> India | D15: Share of views | E15: =MAX(Audience_Data!$B$24:$B$29) -> 0.71
A16: 12 | B16: Which device is used most? | C16: =INDEX(Audience_Data!$A$34:$A$37,MATCH(MAX(Audience_Data!$B$34:$B$37),Audience_Data!$B$34:$B$37,0)) -> Mobile | D16: Share of views | E16: =MAX(Audience_Data!$B$34:$B$37) -> 0.76
A17: 13 | B17: Which gender forms the majority of the audience? | C17: =INDEX(Audience_Data!$A$18:$A$20,MATCH(MAX(Audience_Data!$B$18:$B$20),Audience_Data!$B$18:$B$20,0)) -> Male | D17: Share of views | E17: =MAX(Audience_Data!$B$18:$B$20) -> 0.637
A18: 14 | B18: Is the channel growing? (last 3 vs first 3 months, avg monthly views) | C18: =IF(E18>=0,"Growing","Declining") -> Growing | D18: Change in avg monthly views | E18: =AVERAGE(Timing_Trends!D34:D36)/AVERAGE(Timing_Trends!D25:D27)-1 -> 0.52581119
A19: 15 | B19: What does the linear trend project for next month? | C19: =Timing_Trends!B42 -> Sep 26 | D19: Forecast views | E19: =Timing_Trends!D42 -> 580185
A21: Recommendations (auto-generated from the findings above)
A22: 1 | B22: ="Content mix: prioritise "&C5&" ("&TEXT(E5,"#,##0")&" avg views per video). "&IF(C5=C7,"It is also the best category for converting viewers into subscribers ("&TEXT(E7,"0.00%")&" of viewers subscribe).","Use "&C7&" content to convert viewers into subscribers ("&TEXT(E7,"0.00%")&" of viewers subscribe).") -> Content mix: prioritise Career Guidance (54,498 avg views per video). It is also the best category for converting viewers into subscribers (0.43% of viewers subscribe).
A23: 2 | B23: ="Posting schedule: publish flagship videos on "&C8&"; "&C9&" uploads beat the alternative by "&TEXT(E9,"0.0%")&". Test other slots for 4 weeks before committing." -> Posting schedule: publish flagship videos on Sat; Weekend uploads beat the alternative by 21.5%. Test other slots for 4 weeks before committing.
A24: 3 | B24: ="Video length: for long-form videos aim for the "&C10&" range, which has the highest average views per video ("&TEXT(E10,"#,##0")&")." -> Video length: for long-form videos aim for the 5-10 min range, which has the highest average views per video (37,629).
A25: 4 | B25: ="Formats: "&C11&" wins on views per video, while "&C12&" drives "&TEXT(E12,"0.0%")&" of watch hours. Use Shorts as a discovery funnel that points to long-form videos." -> Formats: Short wins on views per video, while Long-form drives 93.8% of watch hours. Use Shorts as a discovery funnel that points to long-form videos.
A26: 5 | B26: ="Audience: design hooks and thumbnails for the "&C14&" age group ("&TEXT(E14,"0.0%")&" of views), mostly watching on "&C16&" and located in "&C15&"." -> Audience: design hooks and thumbnails for the 18-24 age group (43.0% of views), mostly watching on Mobile and located in India.
A27: 6 | B27: ="Discovery: "&C13&" is the largest traffic source ("&TEXT(E13,"0.0%")&" of views). Optimise titles, thumbnails and metadata for it." -> Discovery: Suggested videos is the largest traffic source (27.0% of views). Optimise titles, thumbnails and metadata for it.
A28: 7 | B28: ="Growth: average monthly views are "&LOWER(C18)&" ("&TEXT(E18,"0.0%")&"); the linear trend projects about "&TEXT(E19,"#,##0")&" views next month." -> Growth: average monthly views are growing (52.6%); the linear trend projects about 580,185 views next month.
A30: Limitations
A31: 1. The dataset is a simulated sample of 144 videos (Sep 2025 - Aug 2026) built for this project, not real channel data. Replace Videos_Data and Audience_Data with a YouTube Studio export to analyse a real channel.
A32: 2. CTR is approximated as Views / Impressions. YouTube's official impression CTR uses clicks on impressions and will differ slightly.
A33: 3. Correlation shows association, not causation. Averages are sensitive to viral outliers, so compare with the median in Stats_Correlation.
A34: 4. Audience segment tables are illustrative inputs and are not reconciled to video-level watch time.

Sheet Videos_Data
A1: Video ID | B1: Title | C1: Category | D1: Format | E1: Publish Date | F1: Duration (min) | G1: Impressions | H1: Views | I1: Likes | J1: Comments | K1: Shares | L1: Watch Time (hrs) | M1: Subscribers Gained | N1: Month | O1: Day of Week | P1: CTR (Views / Impr.) | Q1: Engagement Rate | R1: Avg View Duration (min) | S1: Avg % Viewed | T1: Sub Conversion | U1: Duration Bucket | V1: Weekend / Weekday
A2: V001 | B2: Business Analyst Salary and Career Path in India | C2: Career Guidance | D2: Long-form | E2: 45901 | F2: 13.9 | G2: 685918 | H2: 46459 | I2: 2639 | J2: 157 | K2: 165 | L2: 4981 | M2: 307 | N2: =DATE(YEAR(E2),MONTH(E2),1) -> 45901 | O2: =CHOOSE(WEEKDAY(E2,2),"Mon","Tue","Wed","Thu","Fri","Sat","Sun") -> Mon | P2: =IFERROR(H2/G2,0) -> 0.067732586 | Q2: =IFERROR((I2+J2+K2)/H2,0) -> 0.063733615 | R2: =IFERROR(L2*60/H2,0) -> 6.4327687 | S2: =IFERROR(R2/F2,0) -> 0.46278911 | T2: =IFERROR(M2/H2,0) -> 0.0066079769 | U2: =IF(F2<1,"Under 1 min",IF(F2<5,"1-5 min",IF(F2<10,"5-10 min",IF(F2<20,"10-20 min","20+ min")))) -> 10-20 min | V2: =IF(WEEKDAY(E2,2)>5,"Weekend","Weekday") -> Weekday
A3: V002 | B3: SIP Explained for Beginners | C3: Finance & Investing | D3: Long-form | E3: 45904 | F3: 13 | G3: 778862 | H3: 50782 | I3: 1890 | J3: 187 | K3: 160 | L3: 4730.3 | M3: 267 | N3: =DATE(YEAR(E3),MONTH(E3),1) -> 45901 | O3: =CHOOSE(WEEKDAY(E3,2),"Mon","Tue","Wed","Thu","Fri","Sat","Sun") -> Thu | P3: =IFERROR(H3/G3,0) -> 0.065200254 | Q3: =IFERROR((I3+J3+K3)/H3,0) -> 0.044051042 | R3: =IFERROR(L3*60/H3,0) -> 5.5889488 | S3: =IFERROR(R3/F3,0) -> 0.42991914 | T3: =IFERROR(M3/H3,0) -> 0.0052577685 | U3: =IF(F3<1,"Under 1 min",IF(F3<5,"1-5 min",IF(F3<10,"5-10 min",IF(F3<20,"10-20 min","20+ min")))) -> 10-20 min | V3: =IF(WEEKDAY(E3,2)>5,"Weekend","Weekday") -> Weekday
A4: V003 | B4: Nykaa SWOT Analysis for BBA Students | C4: Business Explainers | D4: Long-form | E4: 45909 | F4: 10.1 | G4: 264296 | H4: 17428 | I4: 787 | J4: 65 | K4: 103 | L4: 1533.2 | M4: 76 | N4: =DATE(YEAR(E4),MONTH(E4),1) -> 45901 | O4: =CHOOSE(WEEKDAY(E4,2),"Mon","Tue","Wed","Thu","Fri","Sat","Sun") -> Tue | P4: =IFERROR(H4/G4,0) -> 0.065941217 | Q4: =IFERROR((I4+J4+K4)/H4,0) -> 0.054796879 | R4: =IFERROR(L4*60/H4,0) -> 5.2784026 | S4: =IFERROR(R4/F4,0) -> 0.52261412 | T4: =IFERROR(M4/H4,0) -> 0.0043607987 | U4: =IF(F4<1,"Under 1 min",IF(F4<5,"1-5 min",IF(F4<10,"5-10 min",IF(F4<20,"10-20 min","20+ min")))) -> 10-20 min | V4: =IF(WEEKDAY(E4,2)>5,"Weekend","Weekday") -> Weekday
A5: V004 | B5: Budgeting in 60 Seconds | C5: Finance & Investing | D5: Short | E5: 45911 | F5: 0.71 | G5: 391422 | H5: 25971 | I5: 861 | J5: 7 | K5: 168 | L5: 307.3 | M5: 36 | N5: =DATE(YEAR(E5),MONTH(E5),1) -> 45901 | O5: =CHOOSE(WEEKDAY(E5,2),"Mon","Tue","Wed","Thu","Fri","Sat","Sun") -> Thu | P5: =IFERROR(H5/G5,0) -> 0.066350384 | Q5: =IFERROR((I5+J5+K5)/H5,0) -> 0.039890647 | R5: =IFERROR(L5*60/H5,0) -> 0.70994571 | S5: =IFERROR(R5/F5,0) -> 0.99992353 | T5: =IFERROR(M5/H5,0) -> 0.0013861615 | U5: =IF(F5<1,"Under 1 min",IF(F5<5,"1-5 min",IF(F5<10,"5-10 min",IF(F5<20,"10-20 min","20+ min")))) -> Under 1 min | V5: =IF(WEEKDAY(E5,2)>5,"Weekend","Weekday") -> Weekday
A6: V005 | B6: Budgeting: Common Mistakes to Avoid | C6: Finance & Investing | D6: Long-form | E6: 45917 | F6: 16.3 | G6: 362080 | H6: 20977 | I6: 838 | J6: 76 | K6: 114 | L6: 2213.3 | M6: 68 | N6: =DATE(YEAR(E6),MONTH(E6),1) -> 45901 | O6: =CHOOSE(WEEKDAY(E6,2),"Mon","Tue","Wed","Thu","Fri","Sat","Sun") -> Wed | P6: =IFERROR(H6/G6,0) -> 0.057934711 | Q6: =IFERROR((I6+J6+K6)/H6,0) -> 0.049006054 | R6: =IFERROR(L6*60/H6,0) -> 6.3306479 | S6: =IFERROR(R6/F6,0) -> 0.3883833 | T6: =IFERROR(M6/H6,0) -> 0.0032416456 | U6: =IF(F6<1,"Under 1 min",IF(F6<5,"1-5 min",IF(F6<10,"5-10 min",IF(F6<20,"10-20 min","20+ min")))) -> 10-20 min | V6: =IF(WEEKDAY(E6,2)>5,"Weekend","Weekday") -> Weekday
A7: V006 | B7: Compound Interest Explained for Beginners | C7: Finance & Investing | D7: Long-form | E7: 45922 | F7: 11.4 | G7: 389115 | H7: 24309 | I7: 873 | J7: 55 | K7: 94 | L7: 2060.1 | M7: 101 | N7: =DATE(YEAR(E7),MONTH(E7),1) -> 45901 | O7: =CHOOSE(WEEKDAY(E7,2),"Mon","Tue","Wed","Thu","Fri","Sat","Sun") -> Mon | P7: =IFERROR(H7/G7,0) -> 0.062472534 | Q7: =IFERROR((I7+J7+K7)/H7,0) -> 0.042042042 | R7: =IFERROR(L7*60/H7,0) -> 5.0847834 | S7: =IFERROR(R7/F7,0) -> 0.44603363 | T7: =IFERROR(M7/H7,0) -> 0.0041548398 | U7: =IF(F7<1,"Under 1 min",IF(F7<5,"1-5 min",IF(F7<10,"5-10 min",IF(F7<20,"10-20 min","20+ min")))) -> 10-20 min | V7: =IF(WEEKDAY(E7,2)>5,"Weekend","Weekday") -> Weekday
A8: V007 | B8: Notion for Students: Step-by-Step | C8: Excel & Tech Tutorials | D8: Long-form | E8: 45922 | F8: 17.8 | G8: 279597 | H8: 10749 | I8: 349 | J8: 29 | K8: 42 | L8: 908.8 | M8: 71 | N8: =DATE(YEAR(E8),MONTH(E8),1) -> 45901 | O8: =CHOOSE(WEEKDAY(E8,2),"Mon","Tue","Wed","Thu","Fri","Sat","Sun") -> Mon | P8: =IFERROR(H8/G8,0) -> 0.038444619 | Q8: =IFERROR((I8+J8+K8)/H8,0) -> 0.039073402 | R8: =IFERROR(L8*60/H8,0) -> 5.072844 | S8: =IFERROR(R8/F8,0) -> 0.28499124 | T8: =IFERROR(M8/H8,0) -> 0.0066052656 | U8: =IF(F8<1,"Under 1 min",IF(F8<5,"1-5 min",IF(F8<10,"5-10 min",IF(F8<20,"10-20 min","20+ min")))) -> 10-20 min | V8: =IF(WEEKDAY(E8,2)>5,"Weekend","Weekday") -> Weekday
A9: V008 | B9: Budgeting Explained for Beginners | C9: Finance & Investing | D9: Long-form | E9: 45923 | F9: 6.7 | G9: 215440 | H9: 11768 | I9: 614 | J9: 38 | K9: 37 | L9: 736.9 | M9: 35 | N9: =DATE(YEAR(E9),MONTH(E9),1) -> 45901 | O9: =CHOOSE(WEEKDAY(E9,2),"Mon","Tue","Wed","Thu","Fri","Sat","Sun") -> Tue | P9: =IFERROR(H9/G9,0) -> 0.054623097 | Q9: =IFERROR((I9+J9+K9)/H9,0) -> 0.058548606 | R9: =IFERROR(L9*60/H9,0) -> 3.757138 | S9: =IFERROR(R9/F9,0) -> 0.56076687 | T9: =IFERROR(M9/H9,0) -> 0.0029741672 | U9: =IF(F9<1,"Under 1 min",IF(F9<5,"1-5 min",IF(F9<10,"5-10 min",IF(F9<20,"10-20 min","20+ min")))) -> 5-10 min | V9: =IF(WEEKDAY(E9,2)>5,"Weekend","Weekday") -> Weekday
A10: V009 | B10: 3 Quick Tips: Notion | C10: Excel & Tech Tutorials | D10: Short | E10: 45923 | F10: 0.94 | G10: 203717 | H10: 17945 | I10: 462 | J10: 34 | K10: 91 | L10: 272.6 | M10: 45 | N10: =DATE(YEAR(E10),MONTH(E10),1) -> 45901 | O10: =CHOOSE(WEEKDAY(E10,2),"Mon","Tue","Wed","Thu","Fri","Sat","Sun") -> Tue | P10: =IFERROR(H10/G10,0) -> 0.088087887 | Q10: =IFERROR((I10+J10+K10)/H10,0) -> 0.032711062 | R10: =IFERROR(L10*60/H10,0) -> 0.91145166 | S10: =IFERROR(R10/F10,0) -> 0.96962942 | T10: =IFERROR(M10/H10,0) -> 0.0025076623 | U10: =IF(F10<1,"Under 1 min",IF(F10<5,"1-5 min",IF(F10<10,"5-10 min",IF(F10<20,"10-20 min","20+ min")))) -> Under 1 min | V10: =IF(WEEKDAY(E10,2)>5,"Weekend","Weekday") -> Weekday
A11: V010 | B11: 3 Quick Tips: Google Sheets | C11: Excel & Tech Tutorials | D11: Short | E11: 45929 | F11: 0.69 | G11: 435835 | H11: 28680 | I11: 1102 | J11: 83 | K11: 155 | L11: 302.2 | M11: 69 | N11: =DATE(YEAR(E11),MONTH(E11),1) -> 45901 | O11: =CHOOSE(WEEKDAY(E11,2),"Mon","Tue","Wed","Thu","Fri","Sat","Sun") -> Mon | P11: =IFERROR(H11/G11,0) -> 0.06580472 | Q11: =IFERROR((I11+J11+K11)/H11,0) -> 0.046722455 | R11: =IFERROR(L11*60/H11,0) -> 0.63221757 | S11: =IFERROR(R11/F11,0) -> 0.91625735 | T11: =IFERROR(M11/H11,0) -> 0.0024058577 | U11: =IF(F11<1,"Under 1 min",IF(F11<5,"1-5 min",IF(F11<10,"5-10 min",IF(F11<20,"10-20 min","20+ min")))) -> Under 1 min | V11: =IF(WEEKDAY(E11,2)>5,"Weekend","Weekday") -> Weekday
A12: V011 | B12: Canva Beginner Tutorial | C12: Excel & Tech Tutorials | D12: Long-form | E12: 45930 | F12: 18.9 | G12: 264644 | H12: 18075 | I12: 696 | J12: 55 | K12: 58 | L12: 2278.4 | M12: 139 | N12: =DATE(YEAR(E12),MONTH(E12),1) -> 45901 | O12: =CHOOSE(WEEKDAY(E12,2),"Mon","Tue","Wed","Thu","Fri","Sat","Sun") -> Tue | P12: =IFERROR(H12/G12,0) -> 0.0682993 | Q12: =IFERROR((I12+J12+K12)/H12,0) -> 0.044757953 | R12: =IFERROR(L12*60/H12,0) -> 7.5631535 | S12: =IFERROR(R12/F12,0) -> 0.40016685 | T12: =IFERROR(M12/H12,0) -> 0.0076901798 | U12: =IF(F12<1,"Under 1 min",IF(F12<5,"1-5 min",IF(F12<10,"5-10 min",IF(F12<20,"10-20 min","20+ min")))) -> 10-20 min | V12: =IF(WEEKDAY(E12,2)>5,"Weekend","Weekday") -> Weekday
A13: V012 | B13: Excel IF Formulas Tutorial | C13: Excel & Tech Tutorials | D13: Long-form | E13: 45930 | F13: 20.2 | G13: 396540 | H13: 25089 | I13: 772 | J13: 109 | K13: 98 | L13: 2719.9 | M13: 136 | N13: =DATE(YEAR(E13),MONTH(E13),1) -> 45901 | O13: =CHOOSE(WEEKDAY(E13,2),"Mon","Tue","Wed","Thu","Fri","Sat","Sun") -> Tue | P13: =IFERROR(H13/G13,0) -> 0.063269784 | Q13: =IFERROR((I13+J13+K13)/H13,0) -> 0.039021085 | R13: =IFERROR(L13*60/H13,0) -> 6.5046036 | S13: =IFERROR(R13/F13,0) -> 0.32201008 | T13: =IFERROR(M13/H13,0) -> 0.0054207023 | U13: =IF(F13<1,"Under 1 min",IF(F13<5,"1-5 min",IF(F13<10,"5-10 min",IF(F13<20,"10-20 min","20+ min")))) -> 20+ min | V13: =IF(WEEKDAY(E13,2)>5,"Weekend","Weekday") -> Weekday
... A145: V144 | B145: Mutual Funds Explained for Beginners | C145: Finance & Investing | D145: Long-form | E145: 46263 | F145: 14.3 | G145: 1073462 | H145: 53401 | I145: 1790 | J145: 158 | K145: 238 | L145: 5301.7 | M145: 341 | N145: =DATE(YEAR(E145),MONTH(E145),1) -> 46235 | O145: =CHOOSE(WEEKDAY(E145,2),"Mon","Tue","Wed","Thu","Fri","Sat","Sun") -> Sat | P145: =IFERROR(H145/G145,0) -> 0.049746521 | Q145: =IFERROR((I145+J145+K145)/H145,0) -> 0.040935563 | R145: =IFERROR(L145*60/H145,0) -> 5.9568547 | S145: =IFERROR(R145/F145,0) -> 0.41656327 | T145: =IFERROR(M145/H145,0) -> 0.0063856482 | U145: =IF(F145<1,"Under 1 min",IF(F145<5,"1-5 min",IF(F145<10,"5-10 min",IF(F145<20,"10-20 min","20+ min")))) -> 10-20 min | V145: =IF(WEEKDAY(E145,2)>5,"Weekend","Weekday") -> Weekend

Sheet Audience_Data
A1: Audience Data & Analysis
A2: Blue cells on yellow = illustrative inputs (replace with YouTube Studio > Analytics > Audience data). Est. Views = share x total views from Videos_Data.
A3: Total channel views (from Videos_Data) | B3: =SUM(Videos_Data!$H$2:$H$145) -> 5798478
A5: 1. Age group x gender (share of views)
A6: Age Group | B6: Male | C6: Female | D6: Other | E6: Total Share | F6: Est. Views | G6: Avg View Duration (min) | H6: Est. Watch Hours | I6: Share of Watch Time
A7: 13-17 | B7: 0.04 | C7: 0.024 | D7: 0.001 | E7: =SUM(B7:D7) -> 0.065 | F7: =E7*$B$3 -> 376901.07 | G7: 4.1 | H7: =F7*G7/60 -> 25754.906 | I7: =IFERROR(H7/$H$13,0) -> 0.045571135
A8: 18-24 | B8: 0.27 | C8: 0.155 | D8: 0.005 | E8: =SUM(B8:D8) -> 0.43 | F8: =E8*$B$3 -> 2493345.5 | G8: 5.6 | H8: =F8*G8/60 -> 232712.25 | I8: =IFERROR(H8/$H$13,0) -> 0.41176471
A9: 25-34 | B9: 0.175 | C9: 0.092 | D9: 0.003 | E9: =SUM(B9:D9) -> 0.27 | F9: =E9*$B$3 -> 1565589.1 | G9: 6.3 | H9: =F9*G9/60 -> 164386.85 | I9: =IFERROR(H9/$H$13,0) -> 0.29086867
A10: 35-44 | B10: 0.078 | C10: 0.041 | D10: 0.001 | E10: =SUM(B10:D10) -> 0.12 | F10: =E10*$B$3 -> 695817.36 | G10: 6.8 | H10: =F10*G10/60 -> 78859.301 | I10: =IFERROR(H10/$H$13,0) -> 0.13953488
A11: 45-54 | B11: 0.042 | C11: 0.022 | D11: 0.001 | E11: =SUM(B11:D11) -> 0.065 | F11: =E11*$B$3 -> 376901.07 | G11: 6.1 | H11: =F11*G11/60 -> 38318.275 | I11: =IFERROR(H11/$H$13,0) -> 0.067800958
A12: 55+ | B12: 0.032 | C12: 0.017 | D12: 0.001 | E12: =SUM(B12:D12) -> 0.05 | F12: =E12*$B$3 -> 289923.9 | G12: 5.2 | H12: =F12*G12/60 -> 25126.738 | I12: =IFERROR(H12/$H$13,0) -> 0.044459644
A13: Total | B13: =SUM(B7:B12) -> 0.637 | C13: =SUM(C7:C12) -> 0.351 | D13: =SUM(D7:D12) -> 0.012 | E13: =SUM(E7:E12) -> 1 | F13: =SUM(F7:F12) -> 5798478 | G13: =IFERROR(H13*60/F13,0) -> 5.848 | H13: =SUM(H7:H12) -> 565158.32 | I13: =SUM(I7:I12) -> 1 | J13: =IF(ROUND(E13,4)=1,"OK: shares sum to 100%","CHECK: shares must sum to 100%") -> OK: shares sum to 100%
A16: 2. Gender split (derived from the matrix above)
A17: Gender | B17: Share of Views | C17: Est. Views
A18: Male | B18: =B13 -> 0.637 | C18: =B18*$B$3 -> 3693630.5
A19: Female | B19: =C13 -> 0.351 | C19: =B19*$B$3 -> 2035265.8
A20: Other | B20: =D13 -> 0.012 | C20: =B20*$B$3 -> 69581.736
A22: 3. Geography (top countries)
A23: Country | B23: Share of Views | C23: Est. Views | D23: Avg View Duration (min) | E23: Est. Watch Hours | F23: Share of Watch Time
A24: India | B24: 0.71 | C24: =B24*$B$3 -> 4116919.4 | D24: 5.8 | E24: =C24*D24/60 -> 397968.87 | F24: =IFERROR(E24/$E$30,0) -> 0.70877797
A25: USA | B25: 0.08 | C25: =B25*$B$3 -> 463878.24 | D25: 6.4 | E25: =C25*D25/60 -> 49480.346 | F25: =IFERROR(E25/$E$30,0) -> 0.088123924
A26: UK | B26: 0.04 | C26: =B26*$B$3 -> 231939.12 | D26: 6.1 | E26: =C26*D26/60 -> 23580.477 | F26: =IFERROR(E26/$E$30,0) -> 0.041996558
A27: UAE | B27: 0.04 | C27: =B27*$B$3 -> 231939.12 | D27: 5.5 | E27: =C27*D27/60 -> 21261.086 | F27: =IFERROR(E27/$E$30,0) -> 0.037865749
A28: Canada | B28: 0.03 | C28: =B28*$B$3 -> 173954.34 | D28: 6.2 | E28: =C28*D28/60 -> 17975.282 | F28: =IFERROR(E28/$E$30,0) -> 0.032013769
A29: Other countries | B29: 0.1 | C29: =B29*$B$3 -> 579847.8 | D29: 5.3 | E29: =C29*D29/60 -> 51219.889 | F29: =IFERROR(E29/$E$30,0) -> 0.091222031
A30: Total | B30: =SUM(B24:B29) -> 1 | C30: =SUM(C24:C29) -> 5798478 | D30: =IFERROR(E30*60/C30,0) -> 5.81 | E30: =SUM(E24:E29) -> 561485.95 | F30: =SUM(F24:F29) -> 1 | G30: =IF(ROUND(B30,4)=1,"OK: shares sum to 100%","CHECK: shares must sum to 100%") -> OK: shares sum to 100%
A32: 4. Device type
A33: Device | B33: Share of Views | C33: Est. Views | D33: Avg View Duration (min) | E33: Est. Watch Hours | F33: Share of Watch Time
A34: Mobile | B34: 0.76 | C34: =B34*$B$3 -> 4406843.3 | D34: 5.2 | E34: =C34*D34/60 -> 381926.42 | F34: =IFERROR(E34/$E$38,0) -> 0.6739427
A35: Desktop | B35: 0.16 | C35: =B35*$B$3 -> 927756.48 | D35: 8.1 | E35: =C35*D35/60 -> 125247.12 | F35: =IFERROR(E35/$E$38,0) -> 0.22100955
A36: TV | B36: 0.04 | C36: =B36*$B$3 -> 231939.12 | D36: 9.4 | E36: =C36*D36/60 -> 36337.129 | F36: =IFERROR(E36/$E$38,0) -> 0.064120055
A37: Tablet | B37: 0.04 | C37: =B37*$B$3 -> 231939.12 | D37: 6 | E37: =C37*D37/60 -> 23193.912 | F37: =IFERROR(E37/$E$38,0) -> 0.040927694
A38: Total | B38: =SUM(B34:B37) -> 1 | C38: =SUM(C34:C37) -> 5798478 | D38: =IFERROR(E38*60/C38,0) -> 5.864 | E38: =SUM(E34:E37) -> 566704.58 | F38: =SUM(F34:F37) -> 1 | G38: =IF(ROUND(B38,4)=1,"OK: shares sum to 100%","CHECK: shares must sum to 100%") -> OK: shares sum to 100%
A41: 5. Traffic source
A42: Traffic Source | B42: Share of Views | C42: Est. Views | D42: Avg View Duration (min) | E42: Est. Watch Hours | F42: Share of Watch Time
A43: Suggested videos | B43: 0.27 | C43: =B43*$B$3 -> 1565589.1 | D43: 5.4 | E43: =C43*D43/60 -> 140903.02 | F43: =IFERROR(E43/$E$50,0) -> 0.26635002
A44: YouTube search | B44: 0.24 | C44: =B44*$B$3 -> 1391634.7 | D44: 6.9 | E44: =C44*D44/60 -> 160037.99 | F44: =IFERROR(E44/$E$50,0) -> 0.30252101
A45: Browse features | B45: 0.18 | C45: =B45*$B$3 -> 1043726 | D45: 5.9 | E45: =C45*D45/60 -> 102633.06 | F45: =IFERROR(E45/$E$50,0) -> 0.19400804
A46: Shorts feed | B46: 0.12 | C46: =B46*$B$3 -> 695817.36 | D46: 0.6 | E46: =C46*D46/60 -> 6958.1736 | F46: =IFERROR(E46/$E$50,0) -> 0.013153087
A47: External | B47: 0.08 | C47: =B47*$B$3 -> 463878.24 | D47: 6.2 | E47: =C47*D47/60 -> 47934.085 | F47: =IFERROR(E47/$E$50,0) -> 0.090610157
...

Sheet Content_Analysis
A1: Content Analysis
A2: All figures are live formulas over Videos_Data. Green = higher avg views, blue = higher engagement.
A3: 1. Performance by content category
A4: Category | B4: Videos | C4: Total Views | D4: Avg Views / Video | E4: Total Watch Hours | F4: Avg % Viewed | G4: CTR (Views / Impr.) | H4: Engagement Rate | I4: Subs Gained | J4: Sub Conversion | K4: Share of Views | L4: Rank (Avg Views)
A5: Business Explainers | B5: =COUNTIFS(Videos_Data!$C$2:$C$145,$A5) -> 27 | C5: =SUMIFS(Videos_Data!$H$2:$H$145,Videos_Data!$C$2:$C$145,$A5) -> 1109094 | D5: =IFERROR(C5/B5,0) -> 41077.556 | E5: =SUMIFS(Videos_Data!$L$2:$L$145,Videos_Data!$C$2:$C$145,$A5) -> 58851.6 | F5: =IFERROR(AVERAGEIFS(Videos_Data!$S$2:$S$145,Videos_Data!$C$2:$C$145,$A5),0) -> 0.55323713 | G5: =IFERROR(C5/SUMIFS(Videos_Data!$G$2:$G$145,Videos_Data!$C$2:$C$145,$A5),0) -> 0.067795021 | H5: =IFERROR((SUMIFS(Videos_Data!$I$2:$I$145,Videos_Data!$C$2:$C$145,$A5)+SUMIFS(Videos_Data!$J$2:$J$145,Videos_Data!$C$2:$C$145,$A5)+SUMIFS(Videos_Data!$K$2:$K$145,Videos_Data!$C$2:$C$145,$A5))/C5,0) -> 0.047307983 | I5: =SUMIFS(Videos_Data!$M$2:$M$145,Videos_Data!$C$2:$C$145,$A5) -> 3354 | J5: =IFERROR(I5/C5,0) -> 0.0030240899 | K5: =IFERROR(C5/$C$11,0) -> 0.1912733 | L5: =RANK(D5,$D$5:$D$10) -> 3
A6: Career Guidance | B6: =COUNTIFS(Videos_Data!$C$2:$C$145,$A6) -> 39 | C6: =SUMIFS(Videos_Data!$H$2:$H$145,Videos_Data!$C$2:$C$145,$A6) -> 2125437 | D6: =IFERROR(C6/B6,0) -> 54498.385 | E6: =SUMIFS(Videos_Data!$L$2:$L$145,Videos_Data!$C$2:$C$145,$A6) -> 131014.8 | F6: =IFERROR(AVERAGEIFS(Videos_Data!$S$2:$S$145,Videos_Data!$C$2:$C$145,$A6),0) -> 0.51286407 | G6: =IFERROR(C6/SUMIFS(Videos_Data!$G$2:$G$145,Videos_Data!$C$2:$C$145,$A6),0) -> 0.061645622 | H6: =IFERROR((SUMIFS(Videos_Data!$I$2:$I$145,Videos_Data!$C$2:$C$145,$A6)+SUMIFS(Videos_Data!$J$2:$J$145,Videos_Data!$C$2:$C$145,$A6)+SUMIFS(Videos_Data!$K$2:$K$145,Videos_Data!$C$2:$C$145,$A6))/C6,0) -> 0.050336472 | I6: =SUMIFS(Videos_Data!$M$2:$M$145,Videos_Data!$C$2:$C$145,$A6) -> 9045 | J6: =IFERROR(I6/C6,0) -> 0.0042555954 | K6: =IFERROR(C6/$C$11,0) -> 0.36655084 | L6: =RANK(D6,$D$5:$D$10) -> 1
A7: Finance & Investing | B7: =COUNTIFS(Videos_Data!$C$2:$C$145,$A7) -> 29 | C7: =SUMIFS(Videos_Data!$H$2:$H$145,Videos_Data!$C$2:$C$145,$A7) -> 1234019 | D7: =IFERROR(C7/B7,0) -> 42552.379 | E7: =SUMIFS(Videos_Data!$L$2:$L$145,Videos_Data!$C$2:$C$145,$A7) -> 79380.7 | F7: =IFERROR(AVERAGEIFS(Videos_Data!$S$2:$S$145,Videos_Data!$C$2:$C$145,$A7),0) -> 0.51568338 | G7: =IFERROR(C7/SUMIFS(Videos_Data!$G$2:$G$145,Videos_Data!$C$2:$C$145,$A7),0) -> 0.058479202 | H7: =IFERROR((SUMIFS(Videos_Data!$I$2:$I$145,Videos_Data!$C$2:$C$145,$A7)+SUMIFS(Videos_Data!$J$2:$J$145,Videos_Data!$C$2:$C$145,$A7)+SUMIFS(Videos_Data!$K$2:$K$145,Videos_Data!$C$2:$C$145,$A7))/C7,0) -> 0.045628147 | I7: =SUMIFS(Videos_Data!$M$2:$M$145,Videos_Data!$C$2:$C$145,$A7) -> 4866 | J7: =IFERROR(I7/C7,0) -> 0.0039432132 | K7: =IFERROR(C7/$C$11,0) -> 0.21281774 | L7: =RANK(D7,$D$5:$D$10) -> 2
A8: Excel & Tech Tutorials | B8: =COUNTIFS(Videos_Data!$C$2:$C$145,$A8) -> 38 | C8: =SUMIFS(Videos_Data!$H$2:$H$145,Videos_Data!$C$2:$C$145,$A8) -> 1218057 | D8: =IFERROR(C8/B8,0) -> 32054.132 | E8: =SUMIFS(Videos_Data!$L$2:$L$145,Videos_Data!$C$2:$C$145,$A8) -> 55199.9 | F8: =IFERROR(AVERAGEIFS(Videos_Data!$S$2:$S$145,Videos_Data!$C$2:$C$145,$A8),0) -> 0.56632913 | G8: =IFERROR(C8/SUMIFS(Videos_Data!$G$2:$G$145,Videos_Data!$C$2:$C$145,$A8),0) -> 0.069769836 | H8: =IFERROR((SUMIFS(Videos_Data!$I$2:$I$145,Videos_Data!$C$2:$C$145,$A8)+SUMIFS(Videos_Data!$J$2:$J$145,Videos_Data!$C$2:$C$145,$A8)+SUMIFS(Videos_Data!$K$2:$K$145,Videos_Data!$C$2:$C$145,$A8))/C8,0) -> 0.039862667 | I8: =SUMIFS(Videos_Data!$M$2:$M$145,Videos_Data!$C$2:$C$145,$A8) -> 4450 | J8: =IFERROR(I8/C8,0) -> 0.0036533594 | K8: =IFERROR(C8/$C$11,0) -> 0.21006495 | L8: =RANK(D8,$D$5:$D$10) -> 4
A9: Campus Vlogs | B9: =COUNTIFS(Videos_Data!$C$2:$C$145,$A9) -> 5 | C9: =SUMIFS(Videos_Data!$H$2:$H$145,Videos_Data!$C$2:$C$145,$A9) -> 70373 | D9: =IFERROR(C9/B9,0) -> 14074.6 | E9: =SUMIFS(Videos_Data!$L$2:$L$145,Videos_Data!$C$2:$C$145,$A9) -> 4504.3 | F9: =IFERROR(AVERAGEIFS(Videos_Data!$S$2:$S$145,Videos_Data!$C$2:$C$145,$A9),0) -> 0.49192905 | G9: =IFERROR(C9/SUMIFS(Videos_Data!$G$2:$G$145,Videos_Data!$C$2:$C$145,$A9),0) -> 0.065464413 | H9: =IFERROR((SUMIFS(Videos_Data!$I$2:$I$145,Videos_Data!$C$2:$C$145,$A9)+SUMIFS(Videos_Data!$J$2:$J$145,Videos_Data!$C$2:$C$145,$A9)+SUMIFS(Videos_Data!$K$2:$K$145,Videos_Data!$C$2:$C$145,$A9))/C9,0) -> 0.062623449 | I9: =SUMIFS(Videos_Data!$M$2:$M$145,Videos_Data!$C$2:$C$145,$A9) -> 258 | J9: =IFERROR(I9/C9,0) -> 0.0036661788 | K9: =IFERROR(C9/$C$11,0) -> 0.012136461 | L9: =RANK(D9,$D$5:$D$10) -> 5
A10: Interviews & Podcasts | B10: =COUNTIFS(Videos_Data!$C$2:$C$145,$A10) -> 6 | C10: =SUMIFS(Videos_Data!$H$2:$H$145,Videos_Data!$C$2:$C$145,$A10) -> 41498 | D10: =IFERROR(C10/B10,0) -> 6916.3333 | E10: =SUMIFS(Videos_Data!$L$2:$L$145,Videos_Data!$C$2:$C$145,$A10) -> 5424.5 | F10: =IFERROR(AVERAGEIFS(Videos_Data!$S$2:$S$145,Videos_Data!$C$2:$C$145,$A10),0) -> 0.36172755 | G10: =IFERROR(C10/SUMIFS(Videos_Data!$G$2:$G$145,Videos_Data!$C$2:$C$145,$A10),0) -> 0.051328292 | H10: =IFERROR((SUMIFS(Videos_Data!$I$2:$I$145,Videos_Data!$C$2:$C$145,$A10)+SUMIFS(Videos_Data!$J$2:$J$145,Videos_Data!$C$2:$C$145,$A10)+SUMIFS(Videos_Data!$K$2:$K$145,Videos_Data!$C$2:$C$145,$A10))/C10,0) -> 0.038821148 | I10: =SUMIFS(Videos_Data!$M$2:$M$145,Videos_Data!$C$2:$C$145,$A10) -> 90 | J10: =IFERROR(I10/C10,0) -> 0.0021687792 | K10: =IFERROR(C10/$C$11,0) -> 0.0071567056 | L10: =RANK(D10,$D$5:$D$10) -> 6
A11: Total / Overall | B11: =SUM(B5:B10) -> 144 | C11: =SUM(C5:C10) -> 5798478 | D11: =IFERROR(C11/B11,0) -> 40267.208 | E11: =SUM(E5:E10) -> 334375.8 | F11: =AVERAGE(Videos_Data!$S$2:$S$145) -> 0.52808637 | G11: =IFERROR(SUM(Videos_Data!$H$2:$H$145)/SUM(Videos_Data!$G$2:$G$145),0) -> 0.063523135 | H11: =IFERROR((SUM(Videos_Data!$I$2:$I$145)+SUM(Videos_Data!$J$2:$J$145)+SUM(Videos_Data!$K$2:$K$145))/SUM(Videos_Data!$H$2:$H$145),0) -> 0.046621717 | I11: =SUM(I5:I10) -> 22063 | J11: =IFERROR(I11/C11,0) -> 0.003804964 | K11: =SUM(K5:K10) -> 1
A12: Caution: categories with fewer than ~10 videos (small samples) can swing on one or two videos; treat their averages as indicative only.
A14: 2. Long-form vs Shorts
A15: Format | B15: Videos | C15: Total Views | D15: Avg Views / Video | E15: Total Watch Hours | F15: Avg % Viewed | G15: CTR (Views / Impr.) | H15: Engagement Rate | I15: Subs Gained | J15: Sub Conversion | K15: Share of Views | L15: Rank (Avg Views)
A16: Long-form | B16: =COUNTIFS(Videos_Data!$D$2:$D$145,$A16) -> 108 | C16: =SUMIFS(Videos_Data!$H$2:$H$145,Videos_Data!$D$2:$D$145,$A16) -> 3535285 | D16: =IFERROR(C16/B16,0) -> 32734.12 | E16: =SUMIFS(Videos_Data!$L$2:$L$145,Videos_Data!$D$2:$D$145,$A16) -> 313592.1 | F16: =IFERROR(AVERAGEIFS(Videos_Data!$S$2:$S$145,Videos_Data!$D$2:$D$145,$A16),0) -> 0.43150783 | G16: =IFERROR(C16/SUMIFS(Videos_Data!$G$2:$G$145,Videos_Data!$D$2:$D$145,$A16),0) -> 0.055910652 | H16: =IFERROR((SUMIFS(Videos_Data!$I$2:$I$145,Videos_Data!$D$2:$D$145,$A16)+SUMIFS(Videos_Data!$J$2:$J$145,Videos_Data!$D$2:$D$145,$A16)+SUMIFS(Videos_Data!$K$2:$K$145,Videos_Data!$D$2:$D$145,$A16))/C16,0) -> 0.049493039 | I16: =SUMIFS(Videos_Data!$M$2:$M$145,Videos_Data!$D$2:$D$145,$A16) -> 17749 | J16: =IFERROR(I16/C16,0) -> 0.0050205288 | K16: =IFERROR(C16/$C$18,0) -> 0.60969189 | L16: =RANK(D16,$D$16:$D$17) -> 2
A17: Short | B17: =COUNTIFS(Videos_Data!$D$2:$D$145,$A17) -> 36 | C17: =SUMIFS(Videos_Data!$H$2:$H$145,Videos_Data!$D$2:$D$145,$A17) -> 2263193 | D17: =IFERROR(C17/B17,0) -> 62866.472 | E17: =SUMIFS(Videos_Data!$L$2:$L$145,Videos_Data!$D$2:$D$145,$A17) -> 20783.7 | F17: =IFERROR(AVERAGEIFS(Videos_Data!$S$2:$S$145,Videos_Data!$D$2:$D$145,$A17),0) -> 0.81782198 | G17: =IFERROR(C17/SUMIFS(Videos_Data!$G$2:$G$145,Videos_Data!$D$2:$D$145,$A17),0) -> 0.080683141 | H17: =IFERROR((SUMIFS(Videos_Data!$I$2:$I$145,Videos_Data!$D$2:$D$145,$A17)+SUMIFS(Videos_Data!$J$2:$J$145,Videos_Data!$D$2:$D$145,$A17)+SUMIFS(Videos_Data!$K$2:$K$145,Videos_Data!$D$2:$D$145,$A17))/C17,0) -> 0.042136486 | I17: =SUMIFS(Videos_Data!$M$2:$M$145,Videos_Data!$D$2:$D$145,$A17) -> 4314 | J17: =IFERROR(I17/C17,0) -> 0.0019061565 | K17: =IFERROR(C17/$C$18,0) -> 0.39030811 | L17: =RANK(D17,$D$16:$D$17) -> 1
A18: Total / Overall | B18: =SUM(B16:B17) -> 144 | C18: =SUM(C16:C17) -> 5798478 | D18: =IFERROR(C18/B18,0) -> 40267.208 | E18: =SUM(E16:E17) -> 334375.8 | F18: =AVERAGE(Videos_Data!$S$2:$S$145) -> 0.52808637 | G18: =IFERROR(SUM(Videos_Data!$H$2:$H$145)/SUM(Videos_Data!$G$2:$G$145),0) -> 0.063523135 | H18: =IFERROR((SUM(Videos_Data!$I$2:$I$145)+SUM(Videos_Data!$J$2:$J$145)+SUM(Videos_Data!$K$2:$K$145))/SUM(Videos_Data!$H$2:$H$145),0) -> 0.046621717 | I18: =SUM(I16:I17) -> 22063 | J18: =IFERROR(I18/C18,0) -> 0.003804964 | K18: =SUM(K16:K17) -> 1
A21: 3. Performance by video duration
A22: Duration Bucket | B22: Videos | C22: Total Views | D22: Avg Views / Video | E22: Total Watch Hours | F22: Avg % Viewed | G22: CTR (Views / Impr.) | H22: Engagement Rate | I22: Subs Gained | J22: Sub Conversion | K22: Share of Views | L22: Rank (Avg Views)
A23: Under 1 min | B23: =COUNTIFS(Videos_Data!$U$2:$U$145,$A23) -> 36 | C23: =SUMIFS(Videos_Data!$H$2:$H$145,Videos_Data!$U$2:$U$145,$A23) -> 2263193 | D23: =IFERROR(C23/B23,0) -> 62866.472 | E23: =SUMIFS(Videos_Data!$L$2:$L$145,Videos_Data!$U$2:$U$145,$A23) -> 20783.7 | F23: =IFERROR(AVERAGEIFS(Videos_Data!$S$2:$S$145,Videos_Data!$U$2:$U$145,$A23),0) -> 0.81782198 | G23: =IFERROR(C23/SUMIFS(Videos_Data!$G$2:$G$145,Videos_Data!$U$2:$U$145,$A23),0) -> 0.080683141 | H23: =IFERROR((SUMIFS(Videos_Data!$I$2:$I$145,Videos_Data!$U$2:$U$145,$A23)+SUMIFS(Videos_Data!$J$2:$J$145,Videos_Data!$U$2:$U$145,$A23)+SUMIFS(Videos_Data!$K$2:$K$145,Videos_Data!$U$2:$U$145,$A23))/C23,0) -> 0.042136486 | I23: =SUMIFS(Videos_Data!$M$2:$M$145,Videos_Data!$U$2:$U$145,$A23) -> 4314 | J23: =IFERROR(I23/C23,0) -> 0.0019061565 | K23: =IFERROR(C23/$C$28,0) -> 0.39030811 | L23: =RANK(D23,$D$23:$D$27) -> 1
A24: 1-5 min | B24: =COUNTIFS(Videos_Data!$U$2:$U$145,$A24) -> 4 | C24: =SUMIFS(Videos_Data!$H$2:$H$145,Videos_Data!$U$2:$U$145,$A24) -> 83637 | D24: =IFERROR(C24/B24,0) -> 20909.25 | E24: =SUMIFS(Videos_Data!$L$2:$L$145,Videos_Data!$U$2:$U$145,$A24) -> 3194.3 | F24: =IFERROR(AVERAGEIFS(Videos_Data!$S$2:$S$145,Videos_Data!$U$2:$U$145,$A24),0) -> 0.54540684 | G24: =IFERROR(C24/SUMIFS(Videos_Data!$G$2:$G$145,Videos_Data!$U$2:$U$145,$A24),0) -> 0.053777898 | H24: =IFERROR((SUMIFS(Videos_Data!$I$2:$I$145,Videos_Data!$U$2:$U$145,$A24)+SUMIFS(Videos_Data!$J$2:$J$145,Videos_Data!$U$2:$U$145,$A24)+SUMIFS(Videos_Data!$K$2:$K$145,Videos_Data!$U$2:$U$145,$A24))/C24,0) -> 0.055477839 | I24: =SUMIFS(Videos_Data!$M$2:$M$145,Videos_Data!$U$2:$U$145,$A24) -> 429 | J24: =IFERROR(I24/C24,0) -> 0.0051293088 | K24: =IFERROR(C24/$C$28,0) -> 0.014423957 | L24: =RANK(D24,$D$23:$D$27) -> 4
A25: 5-10 min | B25: =COUNTIFS(Videos_Data!$U$2:$U$145,$A25) -> 23 | C25: =SUMIFS(Videos_Data!$H$2:$H$145,Videos_Data!$U$2:$U$145,$A25) -> 865464 | D25: =IFERROR(C25/B25,0) -> 37628.87 | E25: =SUMIFS(Videos_Data!$L$2:$L$145,Videos_Data!$U$2:$U$145,$A25) -> 55878.9 | F25: =IFERROR(AVERAGEIFS(Videos_Data!$S$2:$S$145,Videos_Data!$U$2:$U$145,$A25),0) -> 0.49167647 | G25: =IFERROR(C25/SUMIFS(Videos_Data!$G$2:$G$145,Videos_Data!$U$2:$U$145,$A25),0) -> 0.056851289 | H25: =IFERROR((SUMIFS(Videos_Data!$I$2:$I$145,Videos_Data!$U$2:$U$145,$A25)+SUMIFS(Videos_Data!$J$2:$J$145,Videos_Data!$U$2:$U$145,$A25)+SUMIFS(Videos_Data!$K$2:$K$145,Videos_Data!$U$2:$U$145,$A25))/C25,0) -> 0.050505856 | I25: =SUMIFS(Videos_Data!$M$2:$M$145,Videos_Data!$U$2:$U$145,$A25) -> 4206 | J25: =IFERROR(I25/C25,0) -> 0.0048598209 | K25: =IFERROR(C25/$C$28,0) -> 0.1492571 | L25: =RANK(D25,$D$23:$D$27) -> 2
A26: 10-20 min | B26: =COUNTIFS(Videos_Data!$U$2:$U$145,$A26) -> 70 | C26: =SUMIFS(Videos_Data!$H$2:$H$145,Videos_Data!$U$2:$U$145,$A26) -> 2455942 | D26: =IFERROR(C26/B26,0) -> 35084.886 | E26: =SUMIFS(Videos_Data!$L$2:$L$145,Videos_Data!$U$2:$U$145,$A26) -> 238100.4 | F26: =IFERROR(AVERAGEIFS(Videos_Data!$S$2:$S$145,Videos_Data!$U$2:$U$145,$A26),0) -> 0.41857068 | G26: =IFERROR(C26/SUMIFS(Videos_Data!$G$2:$G$145,Videos_Data!$U$2:$U$145,$A26),0) -> 0.056282028 | H26: =IFERROR((SUMIFS(Videos_Data!$I$2:$I$145,Videos_Data!$U$2:$U$145,$A26)+SUMIFS(Videos_Data!$J$2:$J$145,Videos_Data!$U$2:$U$145,$A26)+SUMIFS(Videos_Data!$K$2:$K$145,Videos_Data!$U$2:$U$145,$A26))/C26,0) -> 0.049190494 | I26: =SUMIFS(Videos_Data!$M$2:$M$145,Videos_Data!$U$2:$U$145,$A26) -> 12447 | J26: =IFERROR(I26/C26,0) -> 0.0050681164 | K26: =IFERROR(C26/$C$28,0) -> 0.42354942 | L26: =RANK(D26,$D$23:$D$27) -> 3
A27: 20+ min | B27: =COUNTIFS(Videos_Data!$U$2:$U$145,$A27) -> 11 | C27: =SUMIFS(Videos_Data!$H$2:$H$145,Videos_Data!$U$2:$U$145,$A27) -> 130242 | D27: =IFERROR(C27/B27,0) -> 11840.182 | E27: =SUMIFS(Videos_Data!$L$2:$L$145,Videos_Data!$U$2:$U$145,$A27) -> 16418.5 | F27: =IFERROR(AVERAGEIFS(Videos_Data!$S$2:$S$145,Videos_Data!$U$2:$U$145,$A27),0) -> 0.34661016 | G27: =IFERROR(C27/SUMIFS(Videos_Data!$G$2:$G$145,Videos_Data!$U$2:$U$145,$A27),0) -> 0.046249019 | H27: =IFERROR((SUMIFS(Videos_Data!$I$2:$I$145,Videos_Data!$U$2:$U$145,$A27)+SUMIFS(Videos_Data!$J$2:$J$145,Videos_Data!$U$2:$U$145,$A27)+SUMIFS(Videos_Data!$K$2:$K$145,Videos_Data!$U$2:$U$145,$A27))/C27,0) -> 0.044624622 | I27: =SUMIFS(Videos_Data!$M$2:$M$145,Videos_Data!$U$2:$U$145,$A27) -> 667 | J27: =IFERROR(I27/C27,0) -> 0.0051212359 | K27: =IFERROR(C27/$C$28,0) -> 0.022461411 | L27: =RANK(D27,$D$23:$D$27) -> 5
A28: Total / Overall | B28: =SUM(B23:B27) -> 144 | C28: =SUM(C23:C27) -> 5798478 | D28: =IFERROR(C28/B28,0) -> 40267.208 | E28: =SUM(E23:E27) -> 334375.8 | F28: =AVERAGE(Videos_Data!$S$2:$S$145) -> 0.52808637 | G28: =IFERROR(SUM(Videos_Data!$H$2:$H$145)/SUM(Videos_Data!$G$2:$G$145),0) -> 0.063523135 | H28: =IFERROR((SUM(Videos_Data!$I$2:$I$145)+SUM(Videos_Data!$J$2:$J$145)+SUM(Videos_Data!$K$2:$K$145))/SUM(Videos_Data!$H$2:$H$145),0) -> 0.046621717 | I28: =SUM(I23:I27) -> 22063 | J28: =IFERROR(I28/C28,0) -> 0.003804964 | K28: =SUM(K23:K27) -> 1

Sheet Timing_Trends
A1: Timing & Trend Analysis
A2: When to publish, and how the channel is growing month by month.
A3: 1. Performance by publishing day
A4: Day | B4: Videos | C4: Total Views | D4: Avg Views / Video | E4: Total Watch Hours | F4: Avg % Viewed | G4: CTR (Views / Impr.) | H4: Engagement Rate | I4: Subs Gained | J4: Sub Conversion | K4: Share of Views | L4: Rank (Avg Views)
A5: Mon | B5: =COUNTIFS(Videos_Data!$O$2:$O$145,$A5) -> 17 | C5: =SUMIFS(Videos_Data!$H$2:$H$145,Videos_Data!$O$2:$O$145,$A5) -> 584514 | D5: =IFERROR(C5/B5,0) -> 34383.176 | E5: =SUMIFS(Videos_Data!$L$2:$L$145,Videos_Data!$O$2:$O$145,$A5) -> 34062.7 | F5: =IFERROR(AVERAGEIFS(Videos_Data!$S$2:$S$145,Videos_Data!$O$2:$O$145,$A5),0) -> 0.51259405 | G5: =IFERROR(C5/SUMIFS(Videos_Data!$G$2:$G$145,Videos_Data!$O$2:$O$145,$A5),0) -> 0.065005292 | H5: =IFERROR((SUMIFS(Videos_Data!$I$2:$I$145,Videos_Data!$O$2:$O$145,$A5)+SUMIFS(Videos_Data!$J$2:$J$145,Videos_Data!$O$2:$O$145,$A5)+SUMIFS(Videos_Data!$K$2:$K$145,Videos_Data!$O$2:$O$145,$A5))/C5,0) -> 0.046067331 | I5: =SUMIFS(Videos_Data!$M$2:$M$145,Videos_Data!$O$2:$O$145,$A5) -> 2467 | J5: =IFERROR(I5/C5,0) -> 0.0042206004 | K5: =IFERROR(C5/$C$12,0) -> 0.10080473 | L5: =RANK(D5,$D$5:$D$11) -> 6
A6: Tue | B6: =COUNTIFS(Videos_Data!$O$2:$O$145,$A6) -> 21 | C6: =SUMIFS(Videos_Data!$H$2:$H$145,Videos_Data!$O$2:$O$145,$A6) -> 607747 | D6: =IFERROR(C6/B6,0) -> 28940.333 | E6: =SUMIFS(Videos_Data!$L$2:$L$145,Videos_Data!$O$2:$O$145,$A6) -> 30013.2 | F6: =IFERROR(AVERAGEIFS(Videos_Data!$S$2:$S$145,Videos_Data!$O$2:$O$145,$A6),0) -> 0.52301498 | G6: =IFERROR(C6/SUMIFS(Videos_Data!$G$2:$G$145,Videos_Data!$O$2:$O$145,$A6),0) -> 0.065973583 | H6: =IFERROR((SUMIFS(Videos_Data!$I$2:$I$145,Videos_Data!$O$2:$O$145,$A6)+SUMIFS(Videos_Data!$J$2:$J$145,Videos_Data!$O$2:$O$145,$A6)+SUMIFS(Videos_Data!$K$2:$K$145,Videos_Data!$O$2:$O$145,$A6))/C6,0) -> 0.046032313 | I6: =SUMIFS(Videos_Data!$M$2:$M$145,Videos_Data!$O$2:$O$145,$A6) -> 2296 | J6: =IFERROR(I6/C6,0) -> 0.0037778878 | K6: =IFERROR(C6/$C$12,0) -> 0.10481147 | L6: =RANK(D6,$D$5:$D$11) -> 7
A7: Wed | B7: =COUNTIFS(Videos_Data!$O$2:$O$145,$A7) -> 23 | C7: =SUMIFS(Videos_Data!$H$2:$H$145,Videos_Data!$O$2:$O$145,$A7) -> 1045270 | D7: =IFERROR(C7/B7,0) -> 45446.522 | E7: =SUMIFS(Videos_Data!$L$2:$L$145,Videos_Data!$O$2:$O$145,$A7) -> 58940.6 | F7: =IFERROR(AVERAGEIFS(Videos_Data!$S$2:$S$145,Videos_Data!$O$2:$O$145,$A7),0) -> 0.55598297 | G7: =IFERROR(C7/SUMIFS(Videos_Data!$G$2:$G$145,Videos_Data!$O$2:$O$145,$A7),0) -> 0.066423461 | H7: =IFERROR((SUMIFS(Videos_Data!$I$2:$I$145,Videos_Data!$O$2:$O$145,$A7)+SUMIFS(Videos_Data!$J$2:$J$145,Videos_Data!$O$2:$O$145,$A7)+SUMIFS(Videos_Data!$K$2:$K$145,Videos_Data!$O$2:$O$145,$A7))/C7,0) -> 0.048033522 | I7: =SUMIFS(Videos_Data!$M$2:$M$145,Videos_Data!$O$2:$O$145,$A7) -> 4036 | J7: =IFERROR(I7/C7,0) -> 0.0038612033 | K7: =IFERROR(C7/$C$12,0) -> 0.18026627 | L7: =RANK(D7,$D$5:$D$11) -> 2
A8: Thu | B8: =COUNTIFS(Videos_Data!$O$2:$O$145,$A8) -> 17 | C8: =SUMIFS(Videos_Data!$H$2:$H$145,Videos_Data!$O$2:$O$145,$A8) -> 652260 | D8: =IFERROR(C8/B8,0) -> 38368.235 | E8: =SUMIFS(Videos_Data!$L$2:$L$145,Videos_Data!$O$2:$O$145,$A8) -> 41386.1 | F8: =IFERROR(AVERAGEIFS(Videos_Data!$S$2:$S$145,Videos_Data!$O$2:$O$145,$A8),0) -> 0.52899347 | G8: =IFERROR(C8/SUMIFS(Videos_Data!$G$2:$G$145,Videos_Data!$O$2:$O$145,$A8),0) -> 0.056856764 | H8: =IFERROR((SUMIFS(Videos_Data!$I$2:$I$145,Videos_Data!$O$2:$O$145,$A8)+SUMIFS(Videos_Data!$J$2:$J$145,Videos_Data!$O$2:$O$145,$A8)+SUMIFS(Videos_Data!$K$2:$K$145,Videos_Data!$O$2:$O$145,$A8))/C8,0) -> 0.046193236 | I8: =SUMIFS(Videos_Data!$M$2:$M$145,Videos_Data!$O$2:$O$145,$A8) -> 2592 | J8: =IFERROR(I8/C8,0) -> 0.0039738754 | K8: =IFERROR(C8/$C$12,0) -> 0.11248814 | L8: =RANK(D8,$D$5:$D$11) -> 4
A9: Fri | B9: =COUNTIFS(Videos_Data!$O$2:$O$145,$A9) -> 28 | C9: =SUMIFS(Videos_Data!$H$2:$H$145,Videos_Data!$O$2:$O$145,$A9) -> 1149772 | D9: =IFERROR(C9/B9,0) -> 41063.286 | E9: =SUMIFS(Videos_Data!$L$2:$L$145,Videos_Data!$O$2:$O$145,$A9) -> 66777.5 | F9: =IFERROR(AVERAGEIFS(Videos_Data!$S$2:$S$145,Videos_Data!$O$2:$O$145,$A9),0) -> 0.52007455 | G9: =IFERROR(C9/SUMIFS(Videos_Data!$G$2:$G$145,Videos_Data!$O$2:$O$145,$A9),0) -> 0.060206508 | H9: =IFERROR((SUMIFS(Videos_Data!$I$2:$I$145,Videos_Data!$O$2:$O$145,$A9)+SUMIFS(Videos_Data!$J$2:$J$145,Videos_Data!$O$2:$O$145,$A9)+SUMIFS(Videos_Data!$K$2:$K$145,Videos_Data!$O$2:$O$145,$A9))/C9,0) -> 0.048200861 | I9: =SUMIFS(Videos_Data!$M$2:$M$145,Videos_Data!$O$2:$O$145,$A9) -> 4124 | J9: =IFERROR(I9/C9,0) -> 0.0035867981 | K9: =IFERROR(C9/$C$12,0) -> 0.19828859 | L9: =RANK(D9,$D$5:$D$11) -> 3
A10: Sat | B10: =COUNTIFS(Videos_Data!$O$2:$O$145,$A10) -> 23 | C10: =SUMIFS(Videos_Data!$H$2:$H$145,Videos_Data!$O$2:$O$145,$A10) -> 1203378 | D10: =IFERROR(C10/B10,0) -> 52320.783 | E10: =SUMIFS(Videos_Data!$L$2:$L$145,Videos_Data!$O$2:$O$145,$A10) -> 55033.2 | F10: =IFERROR(AVERAGEIFS(Videos_Data!$S$2:$S$145,Videos_Data!$O$2:$O$145,$A10),0) -> 0.56013713 | G10: =IFERROR(C10/SUMIFS(Videos_Data!$G$2:$G$145,Videos_Data!$O$2:$O$145,$A10),0) -> 0.066162352 | H10: =IFERROR((SUMIFS(Videos_Data!$I$2:$I$145,Videos_Data!$O$2:$O$145,$A10)+SUMIFS(Videos_Data!$J$2:$J$145,Videos_Data!$O$2:$O$145,$A10)+SUMIFS(Videos_Data!$K$2:$K$145,Videos_Data!$O$2:$O$145,$A10))/C10,0) -> 0.045039879 | I10: =SUMIFS(Videos_Data!$M$2:$M$145,Videos_Data!$O$2:$O$145,$A10) -> 3972 | J10: =IFERROR(I10/C10,0) -> 0.0033007085 | K10: =IFERROR(C10/$C$12,0) -> 0.20753343 | L10: =RANK(D10,$D$5:$D$11) -> 1
A11: Sun | B11: =COUNTIFS(Videos_Data!$O$2:$O$145,$A11) -> 15 | C11: =SUMIFS(Videos_Data!$H$2:$H$145,Videos_Data!$O$2:$O$145,$A11) -> 555537 | D11: =IFERROR(C11/B11,0) -> 37035.8 | E11: =SUMIFS(Videos_Data!$L$2:$L$145,Videos_Data!$O$2:$O$145,$A11) -> 48162.5 | F11: =IFERROR(AVERAGEIFS(Videos_Data!$S$2:$S$145,Videos_Data!$O$2:$O$145,$A11),0) -> 0.47475231 | G11: =IFERROR(C11/SUMIFS(Videos_Data!$G$2:$G$145,Videos_Data!$O$2:$O$145,$A11),0) -> 0.064719616 | H11: =IFERROR((SUMIFS(Videos_Data!$I$2:$I$145,Videos_Data!$O$2:$O$145,$A11)+SUMIFS(Videos_Data!$J$2:$J$145,Videos_Data!$O$2:$O$145,$A11)+SUMIFS(Videos_Data!$K$2:$K$145,Videos_Data!$O$2:$O$145,$A11))/C11,0) -> 0.045854732 | I11: =SUMIFS(Videos_Data!$M$2:$M$145,Videos_Data!$O$2:$O$145,$A11) -> 2576 | J11: =IFERROR(I11/C11,0) -> 0.0046369549 | K11: =IFERROR(C11/$C$12,0) -> 0.095807383 | L11: =RANK(D11,$D$5:$D$11) -> 5
A12: Total / Overall | B12: =SUM(B5:B11) -> 144 | C12: =SUM(C5:C11) -> 5798478 | D12: =IFERROR(C12/B12,0) -> 40267.208 | E12: =SUM(E5:E11) -> 334375.8 | F12: =AVERAGE(Videos_Data!$S$2:$S$145) -> 0.52808637 | G12: =IFERROR(SUM(Videos_Data!$H$2:$H$145)/SUM(Videos_Data!$G$2:$G$145),0) -> 0.063523135 | H12: =IFERROR((SUM(Videos_Data!$I$2:$I$145)+SUM(Videos_Data!$J$2:$J$145)+SUM(Videos_Data!$K$2:$K$145))/SUM(Videos_Data!$H$2:$H$145),0) -> 0.046621717 | I12: =SUM(I5:I11) -> 22063 | J12: =IFERROR(I12/C12,0) -> 0.003804964 | K12: =SUM(K5:K11) -> 1
A15: 2. Weekend vs weekday
A16: Period | B16: Videos | C16: Total Views | D16: Avg Views / Video | E16: Total Watch Hours | F16: Avg % Viewed | G16: CTR (Views / Impr.) | H16: Engagement Rate | I16: Subs Gained | J16: Sub Conversion | K16: Share of Views
A17: Weekday | B17: =COUNTIFS(Videos_Data!$V$2:$V$145,$A17) -> 106 | C17: =SUMIFS(Videos_Data!$H$2:$H$145,Videos_Data!$V$2:$V$145,$A17) -> 4039563 | D17: =IFERROR(C17/B17,0) -> 38109.085 | E17: =SUMIFS(Videos_Data!$L$2:$L$145,Videos_Data!$V$2:$V$145,$A17) -> 231180.1 | F17: =IFERROR(AVERAGEIFS(Videos_Data!$S$2:$S$145,Videos_Data!$V$2:$V$145,$A17),0) -> 0.52867923 | G17: =IFERROR(C17/SUMIFS(Videos_Data!$G$2:$G$145,Videos_Data!$V$2:$V$145,$A17),0) -> 0.062619808 | H17: =IFERROR((SUMIFS(Videos_Data!$I$2:$I$145,Videos_Data!$V$2:$V$145,$A17)+SUMIFS(Videos_Data!$J$2:$J$145,Videos_Data!$V$2:$V$145,$A17)+SUMIFS(Videos_Data!$K$2:$K$145,Videos_Data!$V$2:$V$145,$A17))/C17,0) -> 0.047198422 | I17: =SUMIFS(Videos_Data!$M$2:$M$145,Videos_Data!$V$2:$V$145,$A17) -> 15515 | J17: =IFERROR(I17/C17,0) -> 0.003840762 | K17: =IFERROR(C17/$C$19,0) -> 0.69665919
A18: Weekend | B18: =COUNTIFS(Videos_Data!$V$2:$V$145,$A18) -> 38 | C18: =SUMIFS(Videos_Data!$H$2:$H$145,Videos_Data!$V$2:$V$145,$A18) -> 1758915 | D18: =IFERROR(C18/B18,0) -> 46287.237 | E18: =SUMIFS(Videos_Data!$L$2:$L$145,Videos_Data!$V$2:$V$145,$A18) -> 103195.7 | F18: =IFERROR(AVERAGEIFS(Videos_Data!$S$2:$S$145,Videos_Data!$V$2:$V$145,$A18),0) -> 0.5264326 | G18: =IFERROR(C18/SUMIFS(Videos_Data!$G$2:$G$145,Videos_Data!$V$2:$V$145,$A18),0) -> 0.065699776 | H18: =IFERROR((SUMIFS(Videos_Data!$I$2:$I$145,Videos_Data!$V$2:$V$145,$A18)+SUMIFS(Videos_Data!$J$2:$J$145,Videos_Data!$V$2:$V$145,$A18)+SUMIFS(Videos_Data!$K$2:$K$145,Videos_Data!$V$2:$V$145,$A18))/C18,0) -> 0.045297243 | I18: =SUMIFS(Videos_Data!$M$2:$M$145,Videos_Data!$V$2:$V$145,$A18) -> 6548 | J18: =IFERROR(I18/C18,0) -> 0.0037227495 | K18: =IFERROR(C18/$C$19,0) -> 0.30334081
A19: Total / Overall | B19: =SUM(B17:B18) -> 144 | C19: =SUM(C17:C18) -> 5798478 | D19: =IFERROR(C19/B19,0) -> 40267.208 | E19: =SUM(E17:E18) -> 334375.8 | F19: =AVERAGE(Videos_Data!$S$2:$S$145) -> 0.52808637 | G19: =IFERROR(SUM(Videos_Data!$H$2:$H$145)/SUM(Videos_Data!$G$2:$G$145),0) -> 0.063523135 | H19: =IFERROR((SUM(Videos_Data!$I$2:$I$145)+SUM(Videos_Data!$J$2:$J$145)+SUM(Videos_Data!$K$2:$K$145))/SUM(Videos_Data!$H$2:$H$145),0) -> 0.046621717 | I19: =SUM(I17:I18) -> 22063 | J19: =IFERROR(I19/C19,0) -> 0.003804964 | K19: =SUM(K17:K18) -> 1
A22: 3. Monthly channel trend
A23: Subscribers at start of period (assumption) | D23: 12500
A24: Month | B24: Label | C24: Videos | D24: Views | E24: Avg Views / Video | F24: Watch Hours | G24: Subs Gained | H24: Engagement Rate | I24: MoM Views Growth | J24: Cumulative Subscribers | K24: Trend Index
A25: 45901 | B25: =TEXT(A25,"mmm yy") -> Sep 25 | C25: =COUNTIFS(Videos_Data!$N$2:$N$145,$A25) -> 12 | D25: =SUMIFS(Videos_Data!$H$2:$H$145,Videos_Data!$N$2:$N$145,$A25) -> 298232 | E25: =IFERROR(D25/C25,0) -> 24852.667 | F25: =SUMIFS(Videos_Data!$L$2:$L$145,Videos_Data!$N$2:$N$145,$A25) -> 23044 | G25: =SUMIFS(Videos_Data!$M$2:$M$145,Videos_Data!$N$2:$N$145,$A25) -> 1350 | H25: =IFERROR((SUMIFS(Videos_Data!$I$2:$I$145,Videos_Data!$N$2:$N$145,$A25)+SUMIFS(Videos_Data!$J$2:$J$145,Videos_Data!$N$2:$N$145,$A25)+SUMIFS(Videos_Data!$K$2:$K$145,Videos_Data!$N$2:$N$145,$A25))/D25,0) -> 0.047154564 | J25: =$D$23+G25 -> 13850 | K25: 1
A26: =EDATE(A25,1) -> 45931 | B26: =TEXT(A26,"mmm yy") -> Oct 25 | C26: =COUNTIFS(Videos_Data!$N$2:$N$145,$A26) -> 12 | D26: =SUMIFS(Videos_Data!$H$2:$H$145,Videos_Data!$N$2:$N$145,$A26) -> 394539 | E26: =IFERROR(D26/C26,0) -> 32878.25 | F26: =SUMIFS(Videos_Data!$L$2:$L$145,Videos_Data!$N$2:$N$145,$A26) -> 25081.8 | G26: =SUMIFS(Videos_Data!$M$2:$M$145,Videos_Data!$N$2:$N$145,$A26) -> 1558 | H26: =IFERROR((SUMIFS(Videos_Data!$I$2:$I$145,Videos_Data!$N$2:$N$145,$A26)+SUMIFS(Videos_Data!$J$2:$J$145,Videos_Data!$N$2:$N$145,$A26)+SUMIFS(Videos_Data!$K$2:$K$145,Videos_Data!$N$2:$N$145,$A26))/D26,0) -> 0.042692864 | I26: =IFERROR(D26/D25-1,0) -> 0.32292645 | J26: =J25+G26 -> 15408 | K26: 2
A27: =EDATE(A26,1) -> 45962 | B27: =TEXT(A27,"mmm yy") -> Nov 25 | C27: =COUNTIFS(Videos_Data!$N$2:$N$145,$A27) -> 12 | D27: =SUMIFS(Videos_Data!$H$2:$H$145,Videos_Data!$N$2:$N$145,$A27) -> 351098 | E27: =IFERROR(D27/C27,0) -> 29258.167 | F27: =SUMIFS(Videos_Data!$L$2:$L$145,Videos_Data!$N$2:$N$145,$A27) -> 23839.7 | G27: =SUMIFS(Videos_Data!$M$2:$M$145,Videos_Data!$N$2:$N$145,$A27) -> 1424 | H27: =IFERROR((SUMIFS(Videos_Data!$I$2:$I$145,Videos_Data!$N$2:$N$145,$A27)+SUMIFS(Videos_Data!$J$2:$J$145,Videos_Data!$N$2:$N$145,$A27)+SUMIFS(Videos_Data!$K$2:$K$145,Videos_Data!$N$2:$N$145,$A27))/D27,0) -> 0.046984033 | I27: =IFERROR(D27/D26-1,0) -> -0.11010572 | J27: =J26+G27 -> 16832 | K27: 3
A28: =EDATE(A27,1) -> 45992 | B28: =TEXT(A28,"mmm yy") -> Dec 25 | C28: =COUNTIFS(Videos_Data!$N$2:$N$145,$A28) -> 12 | D28: =SUMIFS(Videos_Data!$H$2:$H$145,Videos_Data!$N$2:$N$145,$A28) -> 522345 | E28: =IFERROR(D28/C28,0) -> 43528.75 | F28: =SUMIFS(Videos_Data!$L$2:$L$145,Videos_Data!$N$2:$N$145,$A28) -> 26667 | G28: =SUMIFS(Videos_Data!$M$2:$M$145,Videos_Data!$N$2:$N$145,$A28) -> 1862 | H28: =IFERROR((SUMIFS(Videos_Data!$I$2:$I$145,Videos_Data!$N$2:$N$145,$A28)+SUMIFS(Videos_Data!$J$2:$J$145,Videos_Data!$N$2:$N$145,$A28)+SUMIFS(Videos_Data!$K$2:$K$145,Videos_Data!$N$2:$N$145,$A28))/D28,0) -> 0.046050024 | I28: =IFERROR(D28/D27-1,0) -> 0.48774701 | J28: =J27+G28 -> 18694 | K28: 4
A29: =EDATE(A28,1) -> 46023 | B29: =TEXT(A29,"mmm yy") -> Jan 26 | C29: =COUNTIFS(Videos_Data!$N$2:$N$145,$A29) -> 12 | D29: =SUMIFS(Videos_Data!$H$2:$H$145,Videos_Data!$N$2:$N$145,$A29) -> 747752 | E29: =IFERROR(D29/C29,0) -> 62312.667 | F29: =SUMIFS(Videos_Data!$L$2:$L$145,Videos_Data!$N$2:$N$145,$A29) -> 40031.6 | G29: =SUMIFS(Videos_Data!$M$2:$M$145,Videos_Data!$N$2:$N$145,$A29) -> 2699 | H29: =IFERROR((SUMIFS(Videos_Data!$I$2:$I$145,Videos_Data!$N$2:$N$145,$A29)+SUMIFS(Videos_Data!$J$2:$J$145,Videos_Data!$N$2:$N$145,$A29)+SUMIFS(Videos_Data!$K$2:$K$145,Videos_Data!$N$2:$N$145,$A29))/D29,0) -> 0.049163359 | I29: =IFERROR(D29/D28-1,0) -> 0.43152897 | J29: =J28+G29 -> 21393 | K29: 5
A30: =EDATE(A29,1) -> 46054 | B30: =TEXT(A30,"mmm yy") -> Feb 26 | C30: =COUNTIFS(Videos_Data!$N$2:$N$145,$A30) -> 12 | D30: =SUMIFS(Videos_Data!$H$2:$H$145,Videos_Data!$N$2:$N$145,$A30) -> 405646 | E30: =IFERROR(D30/C30,0) -> 33803.833 | F30: =SUMIFS(Videos_Data!$L$2:$L$145,Videos_Data!$N$2:$N$145,$A30) -> 24767.5 | G30: =SUMIFS(Videos_Data!$M$2:$M$145,Videos_Data!$N$2:$N$145,$A30) -> 1782 | H30: =IFERROR((SUMIFS(Videos_Data!$I$2:$I$145,Videos_Data!$N$2:$N$145,$A30)+SUMIFS(Videos_Data!$J$2:$J$145,Videos_Data!$N$2:$N$145,$A30)+SUMIFS(Videos_Data!$K$2:$K$145,Videos_Data!$N$2:$N$145,$A30))/D30,0) -> 0.043533031 | I30: =IFERROR(D30/D29-1,0) -> -0.45751265 | J30: =J29+G30 -> 23175 | K30: 6
A31: =EDATE(A30,1) -> 46082 | B31: =TEXT(A31,"mmm yy") -> Mar 26 | C31: =COUNTIFS(Videos_Data!$N$2:$N$145,$A31) -> 12 | D31: =SUMIFS(Videos_Data!$H$2:$H$145,Videos_Data!$N$2:$N$145,$A31) -> 532751 | E31: =IFERROR(D31/C31,0) -> 44395.917 | F31: =SUMIFS(Videos_Data!$L$2:$L$145,Videos_Data!$N$2:$N$145,$A31) -> 31263 | G31: =SUMIFS(Videos_Data!$M$2:$M$145,Videos_Data!$N$2:$N$145,$A31) -> 2124 | H31: =IFERROR((SUMIFS(Videos_Data!$I$2:$I$145,Videos_Data!$N$2:$N$145,$A31)+SUMIFS(Videos_Data!$J$2:$J$145,Videos_Data!$N$2:$N$145,$A31)+SUMIFS(Videos_Data!$K$2:$K$145,Videos_Data!$N$2:$N$145,$A31))/D31,0) -> 0.04523877 | I31: =IFERROR(D31/D30-1,0) -> 0.31333971 | J31: =J30+G31 -> 25299 | K31: 7
A32: =EDATE(A31,1) -> 46113 | B32: =TEXT(A32,"mmm yy") -> Apr 26 | C32: =COUNTIFS(Videos_Data!$N$2:$N$145,$A32) -> 12 | D32: =SUMIFS(Videos_Data!$H$2:$H$145,Videos_Data!$N$2:$N$145,$A32) -> 468764 | E32: =IFERROR(D32/C32,0) -> 39063.667 | F32: =SUMIFS(Videos_Data!$L$2:$L$145,Videos_Data!$N$2:$N$145,$A32) -> 23941.5 | G32: =SUMIFS(Videos_Data!$M$2:$M$145,Videos_Data!$N$2:$N$145,$A32) -> 1584 | H32: =IFERROR((SUMIFS(Videos_Data!$I$2:$I$145,Videos_Data!$N$2:$N$145,$A32)+SUMIFS(Videos_Data!$J$2:$J$145,Videos_Data!$N$2:$N$145,$A32)+SUMIFS(Videos_Data!$K$2:$K$145,Videos_Data!$N$2:$N$145,$A32))/D32,0) -> 0.047691376 | I32: =IFERROR(D32/D31-1,0) -> -0.12010677 | J32: =J31+G32 -> 26883 | K32: 8
A33: =EDATE(A32,1) -> 46143 | B33: =TEXT(A33,"mmm yy") -> May 26 | C33: =COUNTIFS(Videos_Data!$N$2:$N$145,$A33) -> 12 | D33: =SUMIFS(Videos_Data!$H$2:$H$145,Videos_Data!$N$2:$N$145,$A33) -> 484604 | E33: =IFERROR(D33/C33,0) -> 40383.667 | F33: =SUMIFS(Videos_Data!$L$2:$L$145,Videos_Data!$N$2:$N$145,$A33) -> 27810.9 | G33: =SUMIFS(Videos_Data!$M$2:$M$145,Videos_Data!$N$2:$N$145,$A33) -> 1442 | H33: =IFERROR((SUMIFS(Videos_Data!$I$2:$I$145,Videos_Data!$N$2:$N$145,$A33)+SUMIFS(Videos_Data!$J$2:$J$145,Videos_Data!$N$2:$N$145,$A33)+SUMIFS(Videos_Data!$K$2:$K$145,Videos_Data!$N$2:$N$145,$A33))/D33,0) -> 0.047626516 | I33: =IFERROR(D33/D32-1,0) -> 0.033790991 | J33: =J32+G33 -> 28325 | K33: 9
A34: =EDATE(A33,1) -> 46174 | B34: =TEXT(A34,"mmm yy") -> Jun 26 | C34: =COUNTIFS(Videos_Data!$N$2:$N$145,$A34) -> 12 | D34: =SUMIFS(Videos_Data!$H$2:$H$145,Videos_Data!$N$2:$N$145,$A34) -> 472995 | E34: =IFERROR(D34/C34,0) -> 39416.25 | F34: =SUMIFS(Videos_Data!$L$2:$L$145,Videos_Data!$N$2:$N$145,$A34) -> 19563.3 | G34: =SUMIFS(Videos_Data!$M$2:$M$145,Videos_Data!$N$2:$N$145,$A34) -> 1703 | H34: =IFERROR((SUMIFS(Videos_Data!$I$2:$I$145,Videos_Data!$N$2:$N$145,$A34)+SUMIFS(Videos_Data!$J$2:$J$145,Videos_Data!$N$2:$N$145,$A34)+SUMIFS(Videos_Data!$K$2:$K$145,Videos_Data!$N$2:$N$145,$A34))/D34,0) -> 0.048070276 | I34: =IFERROR(D34/D33-1,0) -> -0.023955642 | J34: =J33+G34 -> 30028 | K34: 10
A35: =EDATE(A34,1) -> 46204 | B35: =TEXT(A35,"mmm yy") -> Jul 26 | C35: =COUNTIFS(Videos_Data!$N$2:$N$145,$A35) -> 12 | D35: =SUMIFS(Videos_Data!$H$2:$H$145,Videos_Data!$N$2:$N$145,$A35) -> 586765 | E35: =IFERROR(D35/C35,0) -> 48897.083 | F35: =SUMIFS(Videos_Data!$L$2:$L$145,Videos_Data!$N$2:$N$145,$A35) -> 33965 | G35: =SUMIFS(Videos_Data!$M$2:$M$145,Videos_Data!$N$2:$N$145,$A35) -> 2268 | H35: =IFERROR((SUMIFS(Videos_Data!$I$2:$I$145,Videos_Data!$N$2:$N$145,$A35)+SUMIFS(Videos_Data!$J$2:$J$145,Videos_Data!$N$2:$N$145,$A35)+SUMIFS(Videos_Data!$K$2:$K$145,Videos_Data!$N$2:$N$145,$A35))/D35,0) -> 0.048237369 | I35: =IFERROR(D35/D34-1,0) -> 0.24053108 | J35: =J34+G35 -> 32296 | K35: 11
A36: =EDATE(A35,1) -> 46235 | B36: =TEXT(A36,"mmm yy") -> Aug 26 | C36: =COUNTIFS(Videos_Data!$N$2:$N$145,$A36) -> 12 | D36: =SUMIFS(Videos_Data!$H$2:$H$145,Videos_Data!$N$2:$N$145,$A36) -> 532987 | E36: =IFERROR(D36/C36,0) -> 44415.583 | F36: =SUMIFS(Videos_Data!$L$2:$L$145,Videos_Data!$N$2:$N$145,$A36) -> 34400.5 | G36: =SUMIFS(Videos_Data!$M$2:$M$145,Videos_Data!$N$2:$N$145,$A36) -> 2267 | H36: =IFERROR((SUMIFS(Videos_Data!$I$2:$I$145,Videos_Data!$N$2:$N$145,$A36)+SUMIFS(Videos_Data!$J$2:$J$145,Videos_Data!$N$2:$N$145,$A36)+SUMIFS(Videos_Data!$K$2:$K$145,Videos_Data!$N$2:$N$145,$A36))/D36,0) -> 0.044802218 | I36: =IFERROR(D36/D35-1,0) -> -0.091651683 | J36: =J35+G36 -> 34563 | K36: 12
A37: Total | C37: =SUM(C25:C36) -> 144 | D37: =SUM(D25:D36) -> 5798478 | E37: =IFERROR(D37/C37,0) -> 40267.208 | F37: =SUM(F25:F36) -> 334375.8 | G37: =SUM(G25:G36) -> 22063 | H37: =IFERROR((SUM(Videos_Data!$I$2:$I$145)+SUM(Videos_Data!$J$2:$J$145)+SUM(Videos_Data!$K$2:$K$145))/D37,0) -> 0.046621717
A40: 4. Linear trend forecast of monthly views (indicative only)
A41: Month | B41: Label | C41: Trend Index | D41: Forecast Views
A42: =EDATE(A36,1) -> 46266 | B42: =TEXT(A42,"mmm yy") -> Sep 26 | C42: =K36+1 -> 13 | D42: =FORECAST(C42,$D$25:$D$36,$K$25:$K$36) -> 580185
A43: =EDATE(A36,2) -> 46296 | B43: =TEXT(A43,"mmm yy") -> Oct 26 | C43: =K36+2 -> 14 | D43: =FORECAST(C43,$D$25:$D$36,$K$25:$K$36) -> 595104.77
A44: =EDATE(A36,3) -> 46327 | B44: =TEXT(A44,"mmm yy") -> Nov 26 | C44: =K36+3 -> 15 | D44: =FORECAST(C44,$D$25:$D$36,$K$25:$K$36) -> 610024.54
A46: Trend slope (views added per month) | D46: =SLOPE($D$25:$D$36,$K$25:$K$36) -> 14919.769
A47: R-squared of trend line | D47: =RSQ($D$25:$D$36,$K$25:$K$36) -> 0.2080045

Sheet Top_Performers
A1: Top & Bottom Performers
A2: Ranked with LARGE / SMALL and pulled back with INDEX / MATCH (view counts are unique in the dataset).
A3: 1. Top 10 videos by views
A4: Rank | B4: Data Row | C4: Title | D4: Category | E4: Format | F4: Publish Date | G4: Duration (min) | H4: Views | I4: Engagement Rate | J4: CTR | K4: Subs Gained
A5: 1 | B5: =MATCH(LARGE(Videos_Data!$H$2:$H$145,A5),Videos_Data!$H$2:$H$145,0) -> 51 | C5: =INDEX(Videos_Data!$B$2:$B$145,$B5) -> Data Analyst in 60 Seconds | D5: =INDEX(Videos_Data!$C$2:$C$145,$B5) -> Career Guidance | E5: =INDEX(Videos_Data!$D$2:$D$145,$B5) -> Short | F5: =INDEX(Videos_Data!$E$2:$E$145,$B5) -> 46032 | G5: =INDEX(Videos_Data!$F$2:$F$145,$B5) -> 0.92 | H5: =INDEX(Videos_Data!$H$2:$H$145,$B5) -> 237418 | I5: =INDEX(Videos_Data!$Q$2:$Q$145,$B5) -> 0.051238743 | J5: =INDEX(Videos_Data!$P$2:$P$145,$B5) -> 0.082822274 | K5: =INDEX(Videos_Data!$M$2:$M$145,$B5) -> 457
A6: 2 | B6: =MATCH(LARGE(Videos_Data!$H$2:$H$145,A6),Videos_Data!$H$2:$H$145,0) -> 57 | C6: =INDEX(Videos_Data!$B$2:$B$145,$B6) -> Management Trainee Salary and Career Path in India | D6: =INDEX(Videos_Data!$C$2:$C$145,$B6) -> Career Guidance | E6: =INDEX(Videos_Data!$D$2:$D$145,$B6) -> Long-form | F6: =INDEX(Videos_Data!$E$2:$E$145,$B6) -> 46043 | G6: =INDEX(Videos_Data!$F$2:$F$145,$B6) -> 9.7 | H6: =INDEX(Videos_Data!$H$2:$H$145,$B6) -> 112573 | I6: =INDEX(Videos_Data!$Q$2:$Q$145,$B6) -> 0.05933039 | J6: =INDEX(Videos_Data!$P$2:$P$145,$B6) -> 0.072423181 | K6: =INDEX(Videos_Data!$M$2:$M$145,$B6) -> 609
A7: 3 | B7: =MATCH(LARGE(Videos_Data!$H$2:$H$145,A7),Videos_Data!$H$2:$H$145,0) -> 116 | C7: =INDEX(Videos_Data!$B$2:$B$145,$B7) -> Business Analyst in 60 Seconds | D7: =INDEX(Videos_Data!$C$2:$C$145,$B7) -> Career Guidance | E7: =INDEX(Videos_Data!$D$2:$D$145,$B7) -> Short | F7: =INDEX(Videos_Data!$E$2:$E$145,$B7) -> 46192 | G7: =INDEX(Videos_Data!$F$2:$F$145,$B7) -> 0.71 | H7: =INDEX(Videos_Data!$H$2:$H$145,$B7) -> 107201 | I7: =INDEX(Videos_Data!$Q$2:$Q$145,$B7) -> 0.053161818 | J7: =INDEX(Videos_Data!$P$2:$P$145,$B7) -> 0.052735013 | K7: =INDEX(Videos_Data!$M$2:$M$145,$B7) -> 184
A8: 4 | B8: =MATCH(LARGE(Videos_Data!$H$2:$H$145,A8),Videos_Data!$H$2:$H$145,0) -> 84 | C8: =INDEX(Videos_Data!$B$2:$B$145,$B8) -> Amul in 60 Seconds | D8: =INDEX(Videos_Data!$C$2:$C$145,$B8) -> Business Explainers | E8: =INDEX(Videos_Data!$D$2:$D$145,$B8) -> Short | F8: =INDEX(Videos_Data!$E$2:$E$145,$B8) -> 46111 | G8: =INDEX(Videos_Data!$F$2:$F$145,$B8) -> 0.88 | H8: =INDEX(Videos_Data!$H$2:$H$145,$B8) -> 99834 | I8: =INDEX(Videos_Data!$Q$2:$Q$145,$B8) -> 0.038954665 | J8: =INDEX(Videos_Data!$P$2:$P$145,$B8) -> 0.10129796 | K8: =INDEX(Videos_Data!$M$2:$M$145,$B8) -> 135
